<?xml version="1.0" encoding="utf-8"?>
<!-- This URDF was automatically created by SolidWorks to URDF Exporter! Originally created by Stephen Brawner (brawner@gmail.com) 
     Commit Version: 1.6.0-4-g7f85cfe  Build Version: 1.6.7995.38578
     For more information, please see http://wiki.ros.org/sw_urdf_exporter -->
<robot
  name="robot_5A_urdf">
  <link
    name="base_link">
    <inertial>
      <origin
        xyz="-0.07796 0.1305 0.12414"
        rpy="0 0 0" />
      <mass
        value="14.597" />
      <inertia
        ixx="0.69038"
        ixy="0.055653"
        ixz="-0.0081945"
        iyy="0.48743"
        iyz="-0.025908"
        izz="0.72286" />
    </inertial>
    <visual>
      <origin
        xyz="0 0 0"
        rpy="0 0 0" />
      <geometry>
        <mesh
          filename="package://robot_5A_urdf/meshes/base_link.STL" />
      </geometry>
      <material
        name="">
        <color
          rgba="0.79216 0.81961 0.93333 1" />
      </material>
    </visual>
    <collision>
      <origin
        xyz="0 0 0"
        rpy="0 0 0" />
      <geometry>
        <mesh
          filename="package://robot_5A_urdf/meshes/base_link.STL" />
      </geometry>
    </collision>
  </link>
  <link
    name="Link_1">
    <inertial>
      <origin
        xyz="-0.037838 0.064595 0.022488"
        rpy="0 0 0" />
      <mass
        value="14.597" />
      <inertia
        ixx="0.69815"
        ixy="0.021521"
        ixz="0.016097"
        iyy="0.48743"
        iyz="-0.057492"
        izz="0.71509" />
    </inertial>
    <visual>
      <origin
        xyz="0 0 0"
        rpy="0 0 0" />
      <geometry>
        <mesh
          filename="package://robot_5A_urdf/meshes/Link_1.STL" />
      </geometry>
      <material
        name="">
        <color
          rgba="0.79216 0.81961 0.93333 1" />
      </material>
    </visual>
    <collision>
      <origin
        xyz="0 0 0"
        rpy="0 0 0" />
      <geometry>
        <mesh
          filename="package://robot_5A_urdf/meshes/Link_1.STL" />
      </geometry>
    </collision>
  </link>
  <joint
    name="Joint_1"
    type="revolute">
    <origin
      xyz="-0.035213 -0.13463 0.065903"
      rpy="1.5708 0 -0.77692" />
    <parent
      link="base_link" />
    <child
      link="Link_1" />
    <axis
      xyz="0 0 0" />
    <limit
      lower="-1.5707"
      upper="1.5708"
      effort="5"
      velocity="1" />
  </joint>
  <link
    name="Link_2">
    <inertial>
      <origin
        xyz="0.012111 -0.078827 -0.075887"
        rpy="0 0 0" />
      <mass
        value="14.597" />
      <inertia
        ixx="0.72219"
        ixy="0.018773"
        ixz="0.017352"
        iyy="0.47586"
        iyz="-0.026696"
        izz="0.70263" />
    </inertial>
    <visual>
      <origin
        xyz="0 0 0"
        rpy="0 0 0" />
      <geometry>
        <mesh
          filename="package://robot_5A_urdf/meshes/Link_2.STL" />
      </geometry>
      <material
        name="">
        <color
          rgba="0.79216 0.81961 0.93333 1" />
      </material>
    </visual>
    <collision>
      <origin
        xyz="0 0 0"
        rpy="0 0 0" />
      <geometry>
        <mesh
          filename="package://robot_5A_urdf/meshes/Link_2.STL" />
      </geometry>
    </collision>
  </link>
  <joint
    name="Joint_2"
    type="revolute">
    <origin
      xyz="0 0.1655 0"
      rpy="2.7723 0.7558 -3.1416" />
    <parent
      link="Link_1" />
    <child
      link="Link_2" />
    <axis
      xyz="1 0 0" />
    <limit
      lower="-1.5707"
      upper="1.5707"
      effort="5"
      velocity="1" />
  </joint>
  <link
    name="Link_3">
    <inertial>
      <origin
        xyz="0.27499 -0.012111 0.14181"
        rpy="0 0 0" />
      <mass
        value="14.597" />
      <inertia
        ixx="0.49925"
        ixy="0.014358"
        ixz="-0.07396"
        iyy="0.72219"
        iyz="0.021152"
        izz="0.67923" />
    </inertial>
    <visual>
      <origin
        xyz="0 0 0"
        rpy="0 0 0" />
      <geometry>
        <mesh
          filename="package://robot_5A_urdf/meshes/Link_3.STL" />
      </geometry>
      <material
        name="">
        <color
          rgba="0.79216 0.81961 0.93333 1" />
      </material>
    </visual>
    <collision>
      <origin
        xyz="0 0 0"
        rpy="0 0 0" />
      <geometry>
        <mesh
          filename="package://robot_5A_urdf/meshes/Link_3.STL" />
      </geometry>
    </collision>
  </link>
  <joint
    name="Joint_3"
    type="revolute">
    <origin
      xyz="0 0.22112 0"
      rpy="3.1416 -0.22834 -1.5708" />
    <parent
      link="Link_2" />
    <child
      link="Link_3" />
    <axis
      xyz="0 1 0" />
    <limit
      lower="-1.5707"
      upper="1.5707"
      effort="5"
      velocity="1" />
  </joint>
  <link
    name="Link_4">
    <inertial>
      <origin
        xyz="0.12909 -0.44281 0.060383"
        rpy="0 0 0" />
      <mass
        value="14.597" />
      <inertia
        ixx="0.69721"
        ixy="0.065001"
        ixz="-0.02994"
        iyy="0.49925"
        iyz="0.038093"
        izz="0.70421" />
    </inertial>
    <visual>
      <origin
        xyz="0 0 0"
        rpy="0 0 0" />
      <geometry>
        <mesh
          filename="package://robot_5A_urdf/meshes/Link_4.STL" />
      </geometry>
      <material
        name="">
        <color
          rgba="0.79216 0.81961 0.93333 1" />
      </material>
    </visual>
    <collision>
      <origin
        xyz="0 0 0"
        rpy="0 0 0" />
      <geometry>
        <mesh
          filename="package://robot_5A_urdf/meshes/Link_4.STL" />
      </geometry>
    </collision>
  </link>
  <joint
    name="Joint_4"
    type="revolute">
    <origin
      xyz="-0.16783 0.002 0"
      rpy="0 -1.2325 1.5708" />
    <parent
      link="Link_3" />
    <child
      link="Link_4" />
    <axis
      xyz="0 1 0" />
    <limit
      lower="-1.5707"
      upper="1.5707"
      effort="5"
      velocity="1" />
  </joint>
  <link
    name="Link_5">
    <inertial>
      <origin
        xyz="0.49567 0.060383 0.11764"
        rpy="0 0 0" />
      <mass
        value="14.597" />
      <inertia
        ixx="0.48904"
        ixy="-0.047694"
        ixz="-0.045826"
        iyy="0.70421"
        iyz="0.0085269"
        izz="0.70742" />
    </inertial>
    <visual>
      <origin
        xyz="0 0 0"
        rpy="0 0 0" />
      <geometry>
        <mesh
          filename="package://robot_5A_urdf/meshes/Link_5.STL" />
      </geometry>
      <material
        name="">
        <color
          rgba="0.79216 0.81961 0.93333 1" />
      </material>
    </visual>
    <collision>
      <origin
        xyz="0 0 0"
        rpy="0 0 0" />
      <geometry>
        <mesh
          filename="package://robot_5A_urdf/meshes/Link_5.STL" />
      </geometry>
    </collision>
  </link>
  <joint
    name="joint_5"
    type="revolute">
    <origin
      xyz="0 0.05 0"
      rpy="1.5708 0 -1.0816" />
    <parent
      link="Link_4" />
    <child
      link="Link_5" />
    <axis
      xyz="0 1 0" />
    <limit
      lower="-1.5707"
      upper="1.5707"
      effort="5"
      velocity="1" />
  </joint>
  <link
    name="Gripper_Arm_Left">
    <inertial>
      <origin
        xyz="-0.0065946 -0.0031254 -0.00039536"
        rpy="0 0 0" />
      <mass
        value="0.0047829" />
      <inertia
        ixx="2.2361E-07"
        ixy="-1.7848E-12"
        ixz="1.6499E-08"
        iyy="1.128E-06"
        iyz="-1.578E-12"
        izz="9.324E-07" />
    </inertial>
    <visual>
      <origin
        xyz="0 0 0"
        rpy="0 0 0" />
      <geometry>
        <mesh
          filename="package://robot_5A_urdf/meshes/Gripper_Arm_Left.STL" />
      </geometry>
      <material
        name="">
        <color
          rgba="0.9098 0.44314 0.031373 1" />
      </material>
    </visual>
    <collision>
      <origin
        xyz="0 0 0"
        rpy="0 0 0" />
      <geometry>
        <mesh
          filename="package://robot_5A_urdf/meshes/Gripper_Arm_Left.STL" />
      </geometry>
    </collision>
  </link>
  <joint
    name="Joint_Gripper_Arm_Left_Link_5"
    type="revolute">
    <origin
      xyz="0 -0.015 -0.067196"
      rpy="3.1416 -0.66955 1.5708" />
    <parent
      link="Link_5" />
    <child
      link="Gripper_Arm_Left" />
    <axis
      xyz="0 1 0" />
    <limit
      lower="0"
      upper="1.5707"
      effort="5"
      velocity="1" />
  </joint>
  <link
    name="Gripper_Tip_Left">
    <inertial>
      <origin
        xyz="0.0383341002036028 0.00900249975316736 -0.00598336194508436"
        rpy="0 0 0" />
      <mass
        value="0.0102851052587157" />
      <inertia
        ixx="5.52789256250497E-07"
        ixy="4.41064860085597E-10"
        ixz="-6.01969117683768E-07"
        iyy="3.92679929951353E-06"
        iyz="1.00435248420255E-10"
        izz="3.99672165232852E-06" />
    </inertial>
    <visual>
      <origin
        xyz="0 0 0"
        rpy="0 0 0" />
      <geometry>
        <mesh
          filename="package://robot_5A_urdf/meshes/Gripper_Tip_Left.STL" />
      </geometry>
      <material
        name="">
        <color
          rgba="0.6 1 0.27843137254902 1" />
      </material>
    </visual>
    <collision>
      <origin
        xyz="0 0 0"
        rpy="0 0 0" />
      <geometry>
        <mesh
          filename="package://robot_5A_urdf/meshes/Gripper_Tip_Left.STL" />
      </geometry>
    </collision>
  </link>
  <joint
    name="Joint_Gripper_Tip_Left_Gripper_Arm_Left"
    type="revolute">
    <origin
      xyz="-0.023593 0.0056245 0.00020105"
      rpy="0 -0.90125 -3.1416" />
    <parent
      link="Gripper_Arm_Left" />
    <child
      link="Gripper_Tip_Left" />
    <axis
      xyz="0 0 0" />
    <limit
      lower="0"
      upper="1.3"
      effort="5"
      velocity="1" />
  </joint>
  <link
    name="Gripper_Arm_Right">
    <inertial>
      <origin
        xyz="-0.00645261625161411 -0.00312545941778686 0.000406641758048998"
        rpy="0 0 0" />
      <mass
        value="0.00490513551489758" />
      <inertia
        ixx="2.24938996412318E-07"
        ixy="4.32034132283231E-13"
        ixz="-1.91770002858003E-08"
        iyy="1.1349900336246E-06"
        iyz="2.49964766983246E-15"
        izz="9.38746019151626E-07" />
    </inertial>
    <visual>
      <origin
        xyz="0 0 0"
        rpy="0 0 0" />
      <geometry>
        <mesh
          filename="package://robot_5A_urdf/meshes/Gripper_Arm_Right.STL" />
      </geometry>
      <material
        name="">
        <color
          rgba="0.0588235294117647 0.647058823529412 1 1" />
      </material>
    </visual>
    <collision>
      <origin
        xyz="0 0 0"
        rpy="0 0 0" />
      <geometry>
        <mesh
          filename="package://robot_5A_urdf/meshes/Gripper_Arm_Right.STL" />
      </geometry>
    </collision>
  </link>
  <joint
    name="Joint_Gripper_Arm_Right_Link_5"
    type="revolute">
    <origin
      xyz="0 0.013 -0.067196"
      rpy="0 -0.65479 -1.5708" />
    <parent
      link="Link_5" />
    <child
      link="Gripper_Arm_Right" />
    <axis
      xyz="0 1 0" />
    <limit
      lower="-1.5707"
      upper="0"
      effort="5"
      velocity="1" />
  </joint>
  <link
    name="Gripper_Tip_Right">
    <inertial>
      <origin
        xyz="0.0383339490623017 0.00899762411695593 -0.00598346536063252"
        rpy="0 0 0" />
      <mass
        value="0.0102852777939132" />
      <inertia
        ixx="5.52796922266127E-07"
        ixy="-4.20318823311613E-10"
        ixz="-6.01977066358356E-07"
        iyy="3.92681636764725E-06"
        iyz="-7.27543076467185E-11"
        izz="3.99674023370761E-06" />
    </inertial>
    <visual>
      <origin
        xyz="0 0 0"
        rpy="0 0 0" />
      <geometry>
        <mesh
          filename="package://robot_5A_urdf/meshes/Gripper_Tip_Right.STL" />
      </geometry>
      <material
        name="">
        <color
          rgba="0.6 1 0.27843137254902 1" />
      </material>
    </visual>
    <collision>
      <origin
        xyz="0 0 0"
        rpy="0 0 0" />
      <geometry>
        <mesh
          filename="package://robot_5A_urdf/meshes/Gripper_Tip_Right.STL" />
      </geometry>
    </collision>
  </link>
  <joint
    name="Joint_Gripper_Tip_Right_Gripper_Arm_Right"
    type="revolute">
    <origin
      xyz="-0.023592 -0.012375 4.1137E-05"
      rpy="3.1416 0.91601 3.1416" />
    <parent
      link="Gripper_Arm_Right" />
    <child
      link="Gripper_Tip_Right" />
    <axis
      xyz="0 0 0" />
    <limit
      lower="-1.5"
      upper="0"
      effort="5"
      velocity="1" />
  </joint>
  <link
    name="Gripper_Pivot_Left">
    <inertial>
      <origin
        xyz="-0.0464390605773698 0.0031254536455454 -0.0123465860611635"
        rpy="0 0 0" />
      <mass
        value="0.00163752344803861" />
      <inertia
        ixx="1.03008128202862E-08"
        ixy="-8.37520370209941E-23"
        ixz="-4.46677530778635E-22"
        iyy="3.04663146253248E-07"
        iyz="-3.80503081774393E-23"
        izz="3.03761488536761E-07" />
    </inertial>
    <visual>
      <origin
        xyz="0 0 0"
        rpy="0 0 0" />
      <geometry>
        <mesh
          filename="package://robot_5A_urdf/meshes/Gripper_Pivot_Left.STL" />
      </geometry>
      <material
        name="">
        <color
          rgba="0.949019607843137 0 0.968627450980392 1" />
      </material>
    </visual>
    <collision>
      <origin
        xyz="0 0 0"
        rpy="0 0 0" />
      <geometry>
        <mesh
          filename="package://robot_5A_urdf/meshes/Gripper_Pivot_Left.STL" />
      </geometry>
    </collision>
  </link>
  <joint
    name="Joint_Gripper_Pivot_Left_Link_5"
    type="revolute">
    <origin
      xyz="0 0.0050682 -0.061106"
      rpy="0 -0.66955 1.5708" />
    <parent
      link="Link_5" />
    <child
      link="Gripper_Pivot_Left" />
    <axis
      xyz="0 1 0" />
    <limit
      lower="-1.5707"
      upper="1.5707"
      effort="5"
      velocity="1" />
  </joint>
  <link
    name="Gripper_Pivot_Right">
    <inertial>
      <origin
        xyz="-0.0266275838308962 0.00312545364551886 0.0201264783945177"
        rpy="0 0 0" />
      <mass
        value="0.00163752344803858" />
      <inertia
        ixx="1.03008128202859E-08"
        ixy="-2.79690444619492E-22"
        ixz="1.30280946477102E-22"
        iyy="3.04663146253246E-07"
        iyz="-5.9557004103818E-23"
        izz="3.03761488536758E-07" />
    </inertial>
    <visual>
      <origin
        xyz="0 0 0"
        rpy="0 0 0" />
      <geometry>
        <mesh
          filename="package://robot_5A_urdf/meshes/Gripper_Pivot_Right.STL" />
      </geometry>
      <material
        name="">
        <color
          rgba="0.949019607843137 0 0.968627450980392 1" />
      </material>
    </visual>
    <collision>
      <origin
        xyz="0 0 0"
        rpy="0 0 0" />
      <geometry>
        <mesh
          filename="package://robot_5A_urdf/meshes/Gripper_Pivot_Right.STL" />
      </geometry>
    </collision>
  </link>
  <joint
    name="Joint_Gripper_Pivot_Right_Link_5"
    type="revolute">
    <origin
      xyz="0 0.013 -0.067196"
      rpy="3.1416 -0.65479 -1.5708" />
    <parent
      link="Link_5" />
    <child
      link="Gripper_Pivot_Right" />
    <axis
      xyz="0 1 0" />
    <limit
      lower="-1.5707"
      upper="1.5707"
      effort="5"
      velocity="1" />
  </joint>
</robot>